<?xml version="1.0" ?>
<!-- =================================================================================== -->
<!-- |    This document was autogenerated by xacro from robot_proyecto.xacro           | -->
<!-- |    EDITING THIS FILE BY HAND IS NOT RECOMMENDED                                 | -->
<!-- =================================================================================== -->
<robot name="robot_proyecto">
  <material name="silver">
    <color rgba="0.700 0.700 0.700 1.000"/>
  </material>
  <transmission name="revo_2_tran">
    <type>transmission_interface/SimpleTransmission</type>
    <joint name="revo_2">
      <hardwareInterface>hardware_interface/EffortJointInterface</hardwareInterface>
    </joint>
    <actuator name="revo_2_actr">
      <hardwareInterface>hardware_interface/EffortJointInterface</hardwareInterface>
      <mechanicalReduction>1</mechanicalReduction>
    </actuator>
  </transmission>
  <transmission name="revo_3_tran">
    <type>transmission_interface/SimpleTransmission</type>
    <joint name="revo_3">
      <hardwareInterface>hardware_interface/EffortJointInterface</hardwareInterface>
    </joint>
    <actuator name="revo_3_actr">
      <hardwareInterface>hardware_interface/EffortJointInterface</hardwareInterface>
      <mechanicalReduction>1</mechanicalReduction>
    </actuator>
  </transmission>
  <transmission name="revo_4_tran">
    <type>transmission_interface/SimpleTransmission</type>
    <joint name="revo_4">
      <hardwareInterface>hardware_interface/EffortJointInterface</hardwareInterface>
    </joint>
    <actuator name="revo_4_actr">
      <hardwareInterface>hardware_interface/EffortJointInterface</hardwareInterface>
      <mechanicalReduction>1</mechanicalReduction>
    </actuator>
  </transmission>
  <transmission name="revo_5_tran">
    <type>transmission_interface/SimpleTransmission</type>
    <joint name="revo_5">
      <hardwareInterface>hardware_interface/EffortJointInterface</hardwareInterface>
    </joint>
    <actuator name="revo_5_actr">
      <hardwareInterface>hardware_interface/EffortJointInterface</hardwareInterface>
      <mechanicalReduction>1</mechanicalReduction>
    </actuator>
  </transmission>
  <transmission name="revo_6_tran">
    <type>transmission_interface/SimpleTransmission</type>
    <joint name="revo_6">
      <hardwareInterface>hardware_interface/EffortJointInterface</hardwareInterface>
    </joint>
    <actuator name="revo_6_actr">
      <hardwareInterface>hardware_interface/EffortJointInterface</hardwareInterface>
      <mechanicalReduction>1</mechanicalReduction>
    </actuator>
  </transmission>
  <transmission name="revo_1_tran">
    <type>transmission_interface/SimpleTransmission</type>
    <joint name="revo_1">
      <hardwareInterface>hardware_interface/EffortJointInterface</hardwareInterface>
    </joint>
    <actuator name="revo_1_actr">
      <hardwareInterface>hardware_interface/EffortJointInterface</hardwareInterface>
      <mechanicalReduction>1</mechanicalReduction>
    </actuator>
  </transmission>
  <gazebo>
    <plugin filename="libgazebo_ros_control.so" name="gazebo_ros_control">
      <robotNamespace>/robot_proyecto</robotNamespace>
    </plugin>
  </gazebo>
  <gazebo reference="base_link">
    <material>Gazebo/Silver</material>
    <mu1>0.2</mu1>
    <mu2>0.2</mu2>
    <selfCollide>true</selfCollide>
    <gravity>0</gravity>
  </gazebo>
  <gazebo reference="link2_1">
    <material>Gazebo/Silver</material>
    <mu1>0.2</mu1>
    <mu2>0.2</mu2>
    <selfCollide>true</selfCollide>
  </gazebo>
  <gazebo reference="link3_1">
    <material>Gazebo/Silver</material>
    <mu1>0.2</mu1>
    <mu2>0.2</mu2>
    <selfCollide>true</selfCollide>
  </gazebo>
  <gazebo reference="link4_1">
    <material>Gazebo/Silver</material>
    <mu1>0.2</mu1>
    <mu2>0.2</mu2>
    <selfCollide>true</selfCollide>
  </gazebo>
  <gazebo reference="link5_1">
    <material>Gazebo/Silver</material>
    <mu1>0.2</mu1>
    <mu2>0.2</mu2>
    <selfCollide>true</selfCollide>
  </gazebo>
  <gazebo reference="link6_1">
    <material>Gazebo/Silver</material>
    <mu1>0.2</mu1>
    <mu2>0.2</mu2>
    <selfCollide>true</selfCollide>
  </gazebo>
  <gazebo reference="link1_1">
    <material>Gazebo/Silver</material>
    <mu1>0.2</mu1>
    <mu2>0.2</mu2>
    <selfCollide>true</selfCollide>
  </gazebo>
  <link name="world"/>
  <joint name="world_to_base_link=" type="fixed">
    <parent link="world"/>
    <child link="base_link"/>
  </joint>
  <link name="base_link">
    <inertial>
      <origin rpy="0 0 0" xyz="-3.0643350533575795e-15 -5.81835769624857e-17 0.018608735782155033"/>
      <mass value="3.681210634499537"/>
      <inertia ixx="0.007055" ixy="-0.0" ixz="-0.0" iyy="0.007055" iyz="-0.0" izz="0.012041"/>
    </inertial>
    <visual>
      <origin rpy="0 0 0" xyz="0 0 0"/>
      <geometry>
        <mesh filename="package://robot_proyecto_description/meshes/base_link.stl"/>
      </geometry>
      <material name="silver"/>
    </visual>
    <collision>
      <origin rpy="0 0 0" xyz="0 0 0"/>
      <geometry>
        <mesh filename="package://robot_proyecto_description/meshes/base_link.stl"/>
      </geometry>
    </collision>
  </link>
  <link name="link2_1">
    <inertial>
      <origin rpy="0 0 0" xyz="5.03801001463613e-10 -0.002257669022233806 0.13383977677365372"/>
      <mass value="2.0825690848458756"/>
      <inertia ixx="0.009789" ixy="0.0" ixz="-0.0" iyy="0.010731" iyz="0.000234" izz="0.001784"/>
    </inertial>
    <visual>
      <origin rpy="0 0 0" xyz="0.0 -0.0 -0.116"/>
      <geometry>
        <mesh filename="package://robot_proyecto_description/meshes/link2_1.stl"/>
      </geometry>
      <material name="silver"/>
    </visual>
    <collision>
      <origin rpy="0 0 0" xyz="0.0 -0.0 -0.116"/>
      <geometry>
        <mesh filename="package://robot_proyecto_description/meshes/link2_1.stl"/>
      </geometry>
    </collision>
  </link>
  <link name="link3_1">
    <inertial>
      <origin rpy="0 0 0" xyz="-3.551362869946606e-19 0.00434317057470694 0.015475703131377472"/>
      <mass value="1.2719232207208113"/>
      <inertia ixx="0.000833" ixy="-0.0" ixz="-0.0" iyy="0.000832" iyz="-1.7e-05" izz="0.000467"/>
    </inertial>
    <visual>
      <origin rpy="0 0 0" xyz="-0.0 0.005 -0.311"/>
      <geometry>
        <mesh filename="package://robot_proyecto_description/meshes/link3_1.stl"/>
      </geometry>
      <material name="silver"/>
    </visual>
    <collision>
      <origin rpy="0 0 0" xyz="-0.0 0.005 -0.311"/>
      <geometry>
        <mesh filename="package://robot_proyecto_description/meshes/link3_1.stl"/>
      </geometry>
    </collision>
  </link>
  <link name="link4_1">
    <inertial>
      <origin rpy="0 0 0" xyz="0.01068326586499289 0.12176118750392664 -5.493222942482001e-05"/>
      <mass value="1.1883665556027005"/>
      <inertia ixx="0.004412" ixy="-0.000714" ixz="2e-06" iyy="0.000734" iyz="4e-06" izz="0.004962"/>
    </inertial>
    <visual>
      <origin rpy="0 0 0" xyz="-0.0 -0.025 -0.338"/>
      <geometry>
        <mesh filename="package://robot_proyecto_description/meshes/link4_1.stl"/>
      </geometry>
      <material name="silver"/>
    </visual>
    <collision>
      <origin rpy="0 0 0" xyz="-0.0 -0.025 -0.338"/>
      <geometry>
        <mesh filename="package://robot_proyecto_description/meshes/link4_1.stl"/>
      </geometry>
    </collision>
  </link>
  <link name="link5_1">
    <inertial>
      <origin rpy="0 0 0" xyz="2.7841458772332624e-09 -0.005581416777431569 5.13738845105971e-05"/>
      <mass value="0.19239051082723982"/>
      <inertia ixx="4.5e-05" ixy="-0.0" ixz="-0.0" iyy="1.7e-05" iyz="-0.0" izz="4.6e-05"/>
    </inertial>
    <visual>
      <origin rpy="0 0 0" xyz="-0.0 -0.203 -0.337766"/>
      <geometry>
        <mesh filename="package://robot_proyecto_description/meshes/link5_1.stl"/>
      </geometry>
      <material name="silver"/>
    </visual>
    <collision>
      <origin rpy="0 0 0" xyz="-0.0 -0.203 -0.337766"/>
      <geometry>
        <mesh filename="package://robot_proyecto_description/meshes/link5_1.stl"/>
      </geometry>
    </collision>
  </link>
  <link name="link6_1">
    <inertial>
      <origin rpy="0 0 0" xyz="-3.2260852801836125e-07 0.014664378789435384 -1.1553220288229582e-06"/>
      <mass value="0.15787075091036468"/>
      <inertia ixx="2.1e-05" ixy="0.0" ixz="0.0" iyy="1.7e-05" iyz="0.0" izz="2.1e-05"/>
    </inertial>
    <visual>
      <origin rpy="0 0 0" xyz="-0.0 -0.228 -0.338"/>
      <geometry>
        <mesh filename="package://robot_proyecto_description/meshes/link6_1.stl"/>
      </geometry>
      <material name="silver"/>
    </visual>
    <collision>
      <origin rpy="0 0 0" xyz="-0.0 -0.228 -0.338"/>
      <geometry>
        <mesh filename="package://robot_proyecto_description/meshes/link6_1.stl"/>
      </geometry>
    </collision>
  </link>
  <link name="link1_1">
    <inertial>
      <origin rpy="0 0 0" xyz="-2.1512973629865014e-05 -4.170466759319841e-09 0.026937708587327566"/>
      <mass value="2.3854069792520733"/>
      <inertia ixx="0.002223" ixy="-0.0" ixz="2e-06" iyy="0.002484" iyz="-0.0" izz="0.002413"/>
    </inertial>
    <visual>
      <origin rpy="0 0 0" xyz="-0.0 -0.0 -0.05"/>
      <geometry>
        <mesh filename="package://robot_proyecto_description/meshes/link1_1.stl"/>
      </geometry>
      <material name="silver"/>
    </visual>
    <collision>
      <origin rpy="0 0 0" xyz="-0.0 -0.0 -0.05"/>
      <geometry>
        <mesh filename="package://robot_proyecto_description/meshes/link1_1.stl"/>
      </geometry>
    </collision>
  </link>
  <joint name="revo_2" type="revolute">
    <origin rpy="0 0 0" xyz="-0.0 0.0 0.066"/>
    <parent link="link1_1"/>
    <child link="link2_1"/>
    <axis xyz="1.0 0.0 0.0"/>
    <limit effort="100" lower="-1.570796" upper="1.570796" velocity="100"/>
  </joint>
  <joint name="revo_3" type="revolute">
    <origin rpy="0 0 0" xyz="0.0 -0.005 0.195"/>
    <parent link="link2_1"/>
    <child link="link3_1"/>
    <axis xyz="1.0 0.0 0.0"/>
    <limit effort="100" lower="-1.570796" upper="1.570796" velocity="100"/>
  </joint>
  <joint name="revo_4" type="revolute">
    <origin rpy="0 0 0" xyz="0.0 0.03 0.027"/>
    <parent link="link3_1"/>
    <child link="link4_1"/>
    <axis xyz="0.0 1.0 0.0"/>
    <limit effort="100" lower="0.0" upper="6.283185" velocity="100"/>
  </joint>
  <joint name="revo_5" type="revolute">
    <origin rpy="0 0 0" xyz="0.0 0.178 -0.000234"/>
    <parent link="link4_1"/>
    <child link="link5_1"/>
    <axis xyz="-1.0 0.0 0.0"/>
    <limit effort="100" lower="-1.570796" upper="1.570796" velocity="100"/>
  </joint>
  <joint name="revo_6" type="revolute">
    <origin rpy="0 0 0" xyz="0.0 0.025 0.000234"/>
    <parent link="link5_1"/>
    <child link="link6_1"/>
    <axis xyz="0.0 1.0 0.0"/>
    <limit effort="100" lower="0.0" upper="6.283185" velocity="100"/>
  </joint>
  <joint name="revo_1" type="revolute">
    <origin rpy="0 0 0" xyz="0.0 0.0 0.05"/>
    <parent link="base_link"/>
    <child link="link1_1"/>
    <axis xyz="0.0 0.0 1.0"/>
    <limit effort="100" lower="0.0" upper="6.283185" velocity="100"/>
  </joint>
</robot>

